#VRML_SIM R2020b utf8
WorldInfo {
  coordinateSystem "NUE"
}
Viewpoint {
  orientation -0.2668632184741001 0.9197369246598104 0.28786804623465756 1.6010688476543316
  position 2.6420677276449003 2.3590390736425255 -0.0176136008427471
}
TexturedBackground {
}
TexturedBackgroundLight {
}
RectangleArena {
  floorSize 1 2
}
DEF ROBOT1 Robot {
  translation 0 0.045 0.36
  rotation 0 0 -0.9999999999999978 0
  children [
    DEF EMITTER Emitter {
    }
    DEF RECEIVER Receiver {
    }
    DEF HINGE_COVER Solid {
      translation 0 0.03 -3.469446951953614e-18
      children [
        Shape {
          appearance PBRAppearance {
            baseColor 0 0.6509803921568628 1
          }
          geometry Box {
            size 0.030000000000000002 0.019999999999999997 0.05
          }
        }
      ]
      name "hingeCover"
    }
    DEF BODY Shape {
      appearance PBRAppearance {
        baseColor 0.917647 0.145098 0.145098
        roughness 1
        metalness 0
      }
      geometry Box {
        size 0.1 0.05 0.2
      }
    }
    DEF WHEEL1 HingeJoint {
      jointParameters HingeJointParameters {
        position 6.723540149111039e-17
        anchor 0.06 0 0.05
      }
      device [
        RotationalMotor {
          name "wheel1"
        }
      ]
      endPoint Solid {
        translation 0.06 0 0.05
        rotation 9.824307490323283e-16 -9.82913679432505e-16 1 1.5708000000006916
        children [
          DEF WHEEL Shape {
            appearance PBRAppearance {
              baseColor 0.305882 0.898039 0.25098
              roughness 1
              metalness 0
            }
            geometry Cylinder {
              height 0.02
              radius 0.04
              subdivision 24
            }
          }
        ]
        boundingObject USE WHEEL
        physics Physics {
        }
      }
    }
    DEF WHEEL2 HingeJoint {
      jointParameters HingeJointParameters {
        position 6.670640318240083e-17
        anchor -0.06 0 0.05
      }
      device [
        RotationalMotor {
          name "wheel2"
        }
      ]
      endPoint Solid {
        translation -0.06 0 0.05
        rotation 9.833838199347118e-16 -9.83888804930459e-16 1 1.5708000000006936
        children [
          USE WHEEL
        ]
        name "solid(1)"
        boundingObject USE WHEEL
        physics Physics {
        }
      }
    }
    DEF WHEEL3 HingeJoint {
      jointParameters HingeJointParameters {
        position 1.0324509589061627e-16
        anchor 0.06 0 -0.05
      }
      device [
        RotationalMotor {
          name "wheel3"
        }
      ]
      endPoint Solid {
        translation 0.06 0 -0.05
        rotation 1.5411836176911389e-15 -1.541684605418743e-15 1 1.5708000000006943
        children [
          USE WHEEL
        ]
        name "solid(2)"
        boundingObject USE WHEEL
        physics Physics {
        }
      }
    }
    DEF WHEEL4 HingeJoint {
      jointParameters HingeJointParameters {
        position -2.6895122773572173e-17
        anchor -0.06 0 -0.05
      }
      device [
        RotationalMotor {
          name "wheel4"
        }
      ]
      endPoint Solid {
        translation -0.06 0 -0.05
        rotation -4.4795824480189455e-16 4.477977737686118e-16 1 1.5708000000006928
        children [
          USE WHEEL
        ]
        name "solid(3)"
        boundingObject USE WHEEL
        physics Physics {
        }
      }
    }
    DEF POLE HingeJoint {
      jointParameters HingeJointParameters {
        position -4.812689688184746e-16
        anchor 0 0.03000000000047226 0
        minStop -1.3
        maxStop 1.3
      }
      device [
        DEF POLE_POS_SENSOR PositionSensor {
          name "polePosSensor"
        }
      ]
      endPoint Solid {
        translation -1.8379558561220528e-06 0.5299968874104791 -7.306047614849454e-15
        rotation -7.336939675094691e-15 7.325801146553355e-15 1 1.5708000033841338
        children [
          HingeJoint {
            jointParameters HingeJointParameters {
              axis 0 1 0
              anchor 0.49 0 -0.01
              minStop -1.3
              maxStop 1.3
            }
            endPoint DEF CON_SOLID_1 Solid {
              translation 0.49 0 -0.01
              children [
                DEF CON_1 Connector {
                  translation 0 0 -0.005
                  rotation -0.7071067811862364 -0.7071067811862364 9.381857096790023e-07 3.14159
                  isLocked TRUE
                  autoLock TRUE
                  distanceTolerance 0.1
                }
                DEF CON_SHAPE_1 Shape {
                  appearance PBRAppearance {
                    baseColor 0.8 0.0784314 1
                    metalness 0
                  }
                  geometry Box {
                    size 0.01 0.01 0.01
                  }
                }
              ]
              name "solid(1)"
              boundingObject USE CON_SHAPE_1
              physics Physics {
              }
            }
          }
          DEF POLE_ENDPOINT_1 Solid {
            translation 0.5000000000000002 0 0
            scale 0.1 0.1 0.1
            children [
              DEF BALL Shape {
                appearance PBRAppearance {
                  baseColor 0.03137254901960784 0.047058823529411764 1
                  metalness 0
                }
                geometry Sphere {
                  radius 0.1
                }
              }
            ]
            boundingObject USE BALL
            physics Physics {
              density -1
              mass 0.02
            }
          }
          DEF POLE Shape {
            appearance PBRAppearance {
              baseColor 1 0.1568627450980392 0.1568627450980392
              roughness 1
              metalness 0
            }
            geometry Box {
              size 1 0.020000000000000004 0.019999999999999997
            }
          }
        ]
        name "pole"
        boundingObject USE POLE
        physics Physics {
          density -1
          mass 0.2
        }
      }
    }
  ]
  name "robot1"
  boundingObject USE BODY
  physics Physics {
    density -1
    mass 2
  }
  controller "robot_controller"
}
DEF ROBOT2 Robot {
  translation 0 0.045 -0.36
  rotation 0 0 -0.9999999999999978 0
  children [
    DEF EMITTER Emitter {
    }
    DEF RECEIVER Receiver {
    }
    DEF HINGE_COVER Solid {
      translation 0 0.03 -3.469446951953614e-18
      children [
        Shape {
          appearance PBRAppearance {
            baseColor 0 0.6509803921568628 1
          }
          geometry Box {
            size 0.030000000000000002 0.019999999999999997 0.05
          }
        }
      ]
      name "hingeCover"
    }
    DEF BODY Shape {
      appearance PBRAppearance {
        baseColor 0.917647 0.145098 0.145098
        roughness 1
        metalness 0
      }
      geometry Box {
        size 0.1 0.05 0.2
      }
    }
    DEF WHEEL1 HingeJoint {
      jointParameters HingeJointParameters {
        position 6.723540149111039e-17
        anchor 0.06 0 0.05
      }
      device [
        RotationalMotor {
          name "wheel1"
        }
      ]
      endPoint Solid {
        translation 0.06 0 0.05
        rotation 1.7926059467210154e-10 -1.792612536136059e-10 1 1.570800000000691
        children [
          DEF WHEEL Shape {
            appearance PBRAppearance {
              baseColor 0.305882 0.898039 0.25098
              roughness 1
              metalness 0
            }
            geometry Cylinder {
              height 0.02
              radius 0.04
              subdivision 24
            }
          }
        ]
        boundingObject USE WHEEL
        physics Physics {
        }
      }
    }
    DEF WHEEL2 HingeJoint {
      jointParameters HingeJointParameters {
        position 6.670640318240083e-17
        anchor -0.06 0 0.05
      }
      device [
        RotationalMotor {
          name "wheel2"
        }
      ]
      endPoint Solid {
        translation -0.06 0 0.05
        rotation -2.958501727110382e-10 2.95851258930214e-10 1 1.5708000000006928
        children [
          USE WHEEL
        ]
        name "solid(1)"
        boundingObject USE WHEEL
        physics Physics {
        }
      }
    }
    DEF WHEEL3 HingeJoint {
      jointParameters HingeJointParameters {
        position 1.0324509589061627e-16
        anchor 0.06 0 -0.05
      }
      device [
        RotationalMotor {
          name "wheel3"
        }
      ]
      endPoint Solid {
        translation 0.06 0 -0.05
        rotation 2.1800537964184703e-10 -2.1800618091711417e-10 1 1.5708000000006934
        children [
          USE WHEEL
        ]
        name "solid(2)"
        boundingObject USE WHEEL
        physics Physics {
        }
      }
    }
    DEF WHEEL4 HingeJoint {
      jointParameters HingeJointParameters {
        position -2.6895122773572173e-17
        anchor -0.06 0 -0.05
      }
      device [
        RotationalMotor {
          name "wheel4"
        }
      ]
      endPoint Solid {
        translation -0.06 0 -0.05
        rotation -3.5959150777974756e-10 3.595928284736773e-10 1 1.5708000000006928
        children [
          USE WHEEL
        ]
        name "solid(3)"
        boundingObject USE WHEEL
        physics Physics {
        }
      }
    }
    DEF POLE HingeJoint {
      jointParameters HingeJointParameters {
        position -4.812689688184746e-16
        anchor 0 0.03000000000047226 0
        minStop -1.3
        maxStop 1.3
      }
      device [
        DEF POLE_POS_SENSOR PositionSensor {
          name "polePosSensor"
        }
      ]
      endPoint Solid {
        translation -1.837955856122057e-06 0.5299968874104803 -7.236054014524477e-15
        rotation -7.21046968429518e-15 7.367490142797975e-15 1 1.5708000033841318
        children [
          HingeJoint {
            jointParameters HingeJointParameters {
              axis 0 1 0
              anchor 0.49 0 0.01
              minStop -1.3
              maxStop 1.3
            }
            endPoint DEF CON_SOLID_2 Solid {
              translation 0.49 0 0.01
              children [
                DEF CON_2 Connector {
                  translation 0 0 0.005
                  rotation 0.1100430260680405 0.6527641546329925 -0.7495261775549025 4.90708e-06
                  isLocked TRUE
                  autoLock TRUE
                  distanceTolerance 0.1
                }
                DEF CON_SHAPE_2 Shape {
                  appearance PBRAppearance {
                    baseColor 0.8 0.0784314 1
                    metalness 0
                  }
                  geometry Box {
                    size 0.01 0.01 0.01
                  }
                }
              ]
              name "solid(1)"
              boundingObject USE CON_SHAPE_2
              physics Physics {
              }
            }
          }
          DEF POLE_ENDPOINT_2 Solid {
            translation 0.5000000000000002 0 0
            scale 0.1 0.1 0.1
            children [
              DEF BALL Shape {
                appearance PBRAppearance {
                  baseColor 0.03137254901960784 0.047058823529411764 1
                  metalness 0
                }
                geometry Sphere {
                  radius 0.1
                }
              }
            ]
            boundingObject USE BALL
            physics Physics {
              density -1
              mass 0.02
            }
          }
          DEF POLE Shape {
            appearance PBRAppearance {
              baseColor 1 0.1568627450980392 0.1568627450980392
              roughness 1
              metalness 0
            }
            geometry Box {
              size 1 0.020000000000000004 0.019999999999999997
            }
          }
        ]
        name "pole"
        boundingObject USE POLE
        physics Physics {
          density -1
          mass 0.2
        }
      }
    }
  ]
  name "robot2"
  boundingObject USE BODY
  physics Physics {
    density -1
    mass 2
  }
  controller "robot_controller"
}
DEF CONNECTOR_POLE Solid {
  translation 0 1.065 0
  children [
    Connector {
      translation 0 0 0.344
      name "connector1"
      isLocked TRUE
      autoLock TRUE
      distanceTolerance 0.1
    }
    Connector {
      translation 0 0 -0.344
      rotation 0.7071067811862364 -0.7071067811862364 9.381857096790023e-07 3.14159
      name "connector2"
      isLocked TRUE
      autoLock TRUE
      distanceTolerance 0.1
    }
    DEF CON_POLE_BOX Shape {
      appearance PBRAppearance {
        baseColor 0.8 0.0784314 1
        metalness 0
      }
      geometry DEF CON_POLE_BOX Box {
        size 0.01 0.01 0.689
      }
    }
  ]
  name "connector_pole"
  boundingObject USE CON_POLE_BOX
  physics Physics {
    density 10000
  }
}
DEF SUPERVISOR Robot {
  children [
    DEF RECEIVER Receiver {
    }
    DEF EMITTER Emitter {
    }
  ]
  name "supervisor"
  controller "supervisor_manager"
  supervisor TRUE
}
